[INFO     2011-09-05 21:11:21,950 bulkloader.py] Logging to bulkloader-log-20110905.211121
[INFO     2011-09-05 21:11:21,951 bulkloader.py] Throttling transfers:
[INFO     2011-09-05 21:11:21,951 bulkloader.py] Bandwidth: 250000 bytes/second
[INFO     2011-09-05 21:11:21,951 bulkloader.py] HTTP connections: 8/second
[INFO     2011-09-05 21:11:21,951 bulkloader.py] Entities inserted/fetched/modified: 20/second
[INFO     2011-09-05 21:11:21,951 bulkloader.py] Batch Size: 10
[INFO     2011-09-05 21:11:21,967 bulkloader.py] Opening database: bulkloader-progress-20110905.211121.sql3
[DEBUG    2011-09-05 21:11:21,973 adaptive_thread_pool.py] [WorkerThread-0] WorkerThread: started
[DEBUG    2011-09-05 21:11:21,973 adaptive_thread_pool.py] [WorkerThread-1] WorkerThread: started
[DEBUG    2011-09-05 21:11:21,975 adaptive_thread_pool.py] [WorkerThread-2] WorkerThread: started
[DEBUG    2011-09-05 21:11:21,975 adaptive_thread_pool.py] [WorkerThread-3] WorkerThread: started
[DEBUG    2011-09-05 21:11:21,976 adaptive_thread_pool.py] [WorkerThread-4] WorkerThread: started
[DEBUG    2011-09-05 21:11:21,976 adaptive_thread_pool.py] [WorkerThread-5] WorkerThread: started
[DEBUG    2011-09-05 21:11:21,976 adaptive_thread_pool.py] [WorkerThread-6] WorkerThread: started
[DEBUG    2011-09-05 21:11:21,976 adaptive_thread_pool.py] [WorkerThread-7] WorkerThread: started
[DEBUG    2011-09-05 21:11:21,977 adaptive_thread_pool.py] [WorkerThread-8] WorkerThread: started
[DEBUG    2011-09-05 21:11:21,977 adaptive_thread_pool.py] [WorkerThread-9] WorkerThread: started
[DEBUG    2011-09-05 21:11:21,977 bulkloader.py] Configuring remote_api. url_path = /_ah/remote_api, servername = s~tallyhome-gae.appspot.com
[DEBUG    2011-09-05 21:11:21,983 bulkloader.py] Bulkloader using app_id: s~tallyhome-gae
[INFO     2011-09-05 21:11:21,983 bulkloader.py] Connecting to s~tallyhome-gae.appspot.com/_ah/remote_api
[ERROR    2011-09-05 21:11:23,025 bulkloader.py] Exception during authentication
Traceback (most recent call last):
  File "/Users/mblackwell8/Documents/work/tallyhome/server/GoogleAppEngineLauncher.app/Contents/Resources/GoogleAppEngine-default.bundle/Contents/Resources/google_appengine/google/appengine/tools/bulkloader.py", line 3431, in Run
    self.request_manager.Authenticate()
  File "/Users/mblackwell8/Documents/work/tallyhome/server/GoogleAppEngineLauncher.app/Contents/Resources/GoogleAppEngine-default.bundle/Contents/Resources/google_appengine/google/appengine/tools/bulkloader.py", line 1319, in Authenticate
    remote_api_stub.MaybeInvokeAuthentication()
  File "/Users/mblackwell8/Documents/work/tallyhome/server/GoogleAppEngineLauncher.app/Contents/Resources/GoogleAppEngine-default.bundle/Contents/Resources/google_appengine/google/appengine/ext/remote_api/remote_api_stub.py", line 656, in MaybeInvokeAuthentication
    datastore_stub._server.Send(datastore_stub._path, payload=None)
  File "/Users/mblackwell8/Documents/work/tallyhome/server/GoogleAppEngineLauncher.app/Contents/Resources/GoogleAppEngine-default.bundle/Contents/Resources/google_appengine/google/appengine/tools/appengine_rpc.py", line 365, in Send
    f = self.opener.open(req)
  File "/System/Library/Frameworks/Python.framework/Versions/2.7/lib/python2.7/urllib2.py", line 398, in open
    response = meth(req, response)
  File "/System/Library/Frameworks/Python.framework/Versions/2.7/lib/python2.7/urllib2.py", line 511, in http_response
    'http', request, response, code, msg, hdrs)
  File "/System/Library/Frameworks/Python.framework/Versions/2.7/lib/python2.7/urllib2.py", line 436, in error
    return self._call_chain(*args)
  File "/System/Library/Frameworks/Python.framework/Versions/2.7/lib/python2.7/urllib2.py", line 370, in _call_chain
    result = func(*args)
  File "/System/Library/Frameworks/Python.framework/Versions/2.7/lib/python2.7/urllib2.py", line 519, in http_error_default
    raise HTTPError(req.get_full_url(), code, msg, hdrs, fp)
HTTPError: HTTP Error 404: Not Found
[INFO     2011-09-05 21:11:23,030 bulkloader.py] Authentication Failed
